<mujoco model="iiwa7">

    <worldbody>
        <body name="iiwa7_base" pos="0 0 0">
            <!-- robot view -->
            <camera mode="fixed" name="iiwa7_robotview" pos="1.0 0 0.4" quat="0.653 0.271 0.271 0.653"/>
            <inertial diaginertia="0 0 0" mass="0" pos="0 0 0"/>
            <!-- mount attached here -->
            <body name="iiwa7_pedestal" pos="0 0 0.92">
                <inertial diaginertia="6.0869 5.81635 4.20915" mass="60.864" pos="0 0 0" quat="0.659267 -0.259505 -0.260945 0.655692"/>
                <geom conaffinity="0" contype="0" group="1" mesh="iiwa7_pedestal" type="mesh" name="pedestal_vis" rgba="0.2 0.2 0.2 1" />
                <!-- <geom pos="-0.02 0 -0.29" rgba="0.2 0.2 0.2 1" size="0.18 0.31" type="cylinder" name="pedestal_col"/> -->
				<geom type="mesh" group="0" rgba="0.2 0.2 0.2 1" mesh="iiwa7_pedestal" name="iiwa7_pedestal_col"/>
                <body name="iiwa7_link_0">
                    <geom type="mesh" pos="0 0 0" contype="0" conaffinity="0" group="1" rgba="0.4 0.4 0.4 1" name="iiwa7_link_0_visual" mesh="iiwa7_link_0_vis" />
                    <geom type="mesh" pos="0 0 0" rgba="0.4 0.4 0.4 1" contype="0" mesh="iiwa7_link_0_vis" name="iiwa7_link_0_collision" />
                    <body name="iiwa7_link_1" pos="0 0 0.15">
                        <inertial pos="0 -0.03 0.12" quat="0.428904 0.562175 -0.562175 0.428904" mass="3.4525" diaginertia="0.0218946 0.02183 0.00663837" />
                        <joint name="iiwa7_joint_1" pos="0 0 0" axis="0 0 1" limited="true" range="-2.96706 2.96706" damping="0.1" />
                        <geom pos="0 0 0.0075" type="mesh" contype="0" conaffinity="0" group="1" rgba="0.4 0.4 0.4 1" name="iiwa7_link_1_visual" mesh="iiwa7_link_1_vis" />
                        <geom pos="0 0 0.0075" type="mesh" contype="0" rgba="0.4 0.4 0.4 1" mesh="iiwa7_link_1_vis" name="iiwa7_link_1_collision" />
                        <body name="iiwa7_link_2" pos="0 0 0.19" quat="0 0 0.707107 0.707107">
                            <inertial pos="0.0003 0.059 0.042" quat="0.701371 0.0898824 0.0898824 0.701371" mass="3.4821" diaginertia="0.02179 0.0217049 0.00684512" />
                            <joint name="iiwa7_joint_2" pos="0 0 0" axis="0 0 1" limited="true" range="-2.0944 2.0944" damping="0.1" />
                            <geom type="mesh" contype="0" conaffinity="0" group="1" rgba="1 0.423529 0.0392157 1" name="iiwa7_link_2_visual" mesh="iiwa7_link_2_vis" />
                            <geom type="mesh" contype="0" rgba="1 0.423529 0.0392157 1" mesh="iiwa7_link_2_vis" name="iiwa7_link_2_collision" />
                            <body name="iiwa7_link_3" pos="0 0.21 0" quat="0 0 0.707107 0.707107">
                                <inertial pos="0 0.03 0.13" quat="0.56292 0.427927 -0.427927 0.56292" mass="4.05623" diaginertia="0.0321488 0.03204 0.00799117" />
                                <joint name="iiwa7_joint_3" pos="0 0 0" axis="0 0 1" limited="true" range="-2.96706 2.96706" damping="0.1" />
                                <geom pos="0 0 -0.026" type="mesh" contype="0" conaffinity="0" group="1" rgba="0.4 0.4 0.4 1" name="iiwa7_link_3_visual" mesh="iiwa7_link_3_vis" />
                                <geom pos="0 0 -0.026" type="mesh" contype="0" rgba="0.4 0.4 0.4 1" mesh="iiwa7_link_3_vis" name="iiwa7_link_3_collision" />
                                <body name="iiwa7_link_4" pos="0 0 0.19" quat="0.707107 0.707107 0 0">
                                    <inertial pos="0 0.067 0.034" quat="0.991887 -0.127124 0 0" mass="3.4822" diaginertia="0.02178 0.0216947 0.00684029" />
                                    <joint name="iiwa7_joint_4" pos="0 0 0" axis="0 0 1" limited="true" range="-2.0944 2.0944" damping="0.1" />
                                    <geom type="mesh" contype="0" conaffinity="0" group="1" rgba="1 0.423529 0.0392157 1" name="iiwa7_link_4_visual" mesh="iiwa7_link_4_vis" />
                                    <geom type="mesh" contype="0" rgba="1 0.423529 0.0392157 1" mesh="iiwa7_link_4_vis" name="iiwa7_link_4_collision" />
                                    <body name="iiwa7_link_5" pos="0 0.21 0" quat="0 0 0.707107 0.707107">
                                        <inertial pos="0.0001 0.021 0.076" quat="0.365352 0.605407 -0.605407 0.365352" mass="2.1633" diaginertia="0.0131987 0.01287 0.0036293" />
                                        <joint name="iiwa7_joint_5" pos="0 0 0" axis="0 0 1" limited="true" range="-2.96706 2.96706" damping="0.1" />
                                        <geom pos="0 0 -0.026" type="mesh" contype="0" conaffinity="0" group="1" rgba="0.4 0.4 0.4 1" name="iiwa7_link_5_visual" mesh="iiwa7_link_5_vis" />
                                        <geom pos="0 0 -0.026" type="mesh" contype="0" rgba="0.4 0.4 0.4 1" mesh="iiwa7_link_5_vis" name="iiwa7_link_5_collision" />
                                        <body name="iiwa7_link_6" pos="0 0.0607 0.19" quat="0.707107 0.707107 0 0">
                                            <inertial pos="0 0.0006 0.0004" quat="0.996112 0.088097 0 0" mass="2.3466" diaginertia="0.006509 0.00631585 0.00447015" />
                                            <joint name="iiwa7_joint_6" pos="0 0 0" axis="0 0 1" limited="true" range="-2.0944 2.0944" damping="0.1" />
                                            <geom type="mesh" contype="0" conaffinity="0" group="1" mesh="iiwa7_link_6_vis" name="iiwa7_link_6_visual" rgba="1 0.423529 0.0392157 1" />
                                            <geom type="mesh" contype="0" rgba="1 0.423529 0.0392157 1" mesh="iiwa7_link_6_vis" name="iiwa7_link_6_collision" />
                                            <body name="iiwa7_link_7" pos="0 0.081 0.0607" quat="0 0 0.707107 0.707107">
                                                <inertial pos="0 0 0.02" quat="0.923068 0 0 0.384636" mass="3.129" diaginertia="0.0152362 0.0140538 0.002872" />
                                                <joint name="iiwa7_joint_7" pos="0 0 0" axis="0 0 1" limited="true" range="-3.05433 3.05433" damping="0.1" />
                                                <geom pos="0 0 -0.0005" type="mesh" contype="0" conaffinity="0" group="1" rgba="0.4 0.4 0.4 1" mesh="iiwa7_link_7_vis" name="iiwa7_link_7_visual" />
                                                <geom pos="0 0 -0.0005" type="mesh" contype="0" rgba="0.4 0.4 0.4 1" mesh="iiwa7_link_7_vis" name="iiwa7_link_7_collision" />
                                                <body name="iiwa7_right_hand" pos="0 0 0.044" quat="1 0 0 0">
                                                    <!-- This camera points out from the eef. -->
                                                    <camera mode="fixed" name="iiwa7_eye_in_hand" pos="0.05 0 0" quat="0 0.707108 0.707108 0" fovy="75"/>
                                                    <!-- To add gripper -->
                                                    <include file="assets/robotiq_gripper_140.xml"/>
                                                </body>
                                            </body>
                                        </body>
                                    </body>
                                </body>
                            </body>
                        </body>
                    </body>
                </body>
            </body>
        </body>
    </worldbody>
</mujoco>
