<?xml version="1.0" ?>

<mujoco>
  <camera mode="fixed" name="iiwa14_robotview" pos="1.0 0 0.4" quat="0.653 0.271 0.271 0.653"/>
  <inertial diaginertia="0 0 0" mass="0" pos="0 0 0"/>
  <body name="pedestal" pos="0 0 0.92">
      <inertial pos="0 0 0" quat="0.659267 -0.259505 -0.260945 0.655692" mass="60.864" diaginertia="6.0869 5.81635 4.20915" />
      <geom class="pedestal_viz" pos="0.26 0.345 -0.91488" quat="0.5 0.5 -0.5 -0.5" type="mesh" contype="0" conaffinity="0" group="1"  mesh="pedestal" />
      <geom class="pedestal_viz" size="0.18 0.31" pos="-0.02 0 -0.29" type="cylinder" rgba="0.2 0.2 0.2 0" />

    <body name="iiwa14_link_0">
      <!-- <geom class="collision" type="mesh" mesh="iiwa14_link_0_mesh"/> -->
      <geom class="visual" type="mesh" mesh="iiwa14_link_0_mesh" material="iiwa14_grey"/>
      <body name="iiwa14_link_1" pos="0 0 0.1575">
        <joint name="iiwa14_joint_1" axis="0 0 1" limited="true" range="-2.96705972839 2.96705972839"/>
        <inertial euler="0 0 0" pos="0 -0.03 0.12" mass="5.76" diaginertia="0.033 0.0333 0.0123"/>
        <geom class="visual" type="mesh" mesh="iiwa14_link_1_mesh" material="iiwa14_grey"/>
        <geom class="collision" type="mesh" mesh="iiwa14_link_1_mesh" />
        <body name="iiwa14_link_2" euler="1.570796326794897 3.141592653589793 0" pos="0 0 0.2025">
          <joint name="iiwa14_joint_2" axis="0 0 1" limited="true" range="-2.09439510239 2.09439510239"/>
          <inertial euler="0 0 0" pos="0.0003 0.059 0.042" mass="6.35" diaginertia="0.0305 0.0304 0.011"/>
          <geom class="collision" type="mesh" mesh="iiwa14_link_2_mesh"/>
          <geom class="visual" type="mesh" mesh="iiwa14_link_2_mesh" material="iiwa14_orange"/>
          <body name="iiwa14_link_3" euler="1.570796326794897 3.141592653589793 0" pos="0 0.2045 0">
            <joint name="iiwa14_joint_3" axis="0 0 1" limited="true" range="-2.96705972839 2.96705972839"/>
            <inertial euler="0 0 0" pos="0 0.03 0.13" mass="3.5" diaginertia="0.025 0.0238 0.0076"/>
            <geom class="collision" type="mesh" mesh="iiwa14_link_3_mesh"/>
            <geom class="visual" type="mesh" mesh="iiwa14_link_3_mesh" material="iiwa14_grey"/>
            <body name="iiwa14_link_4" euler="1.570796326794897 0 0" pos="0 0 0.2155">
              <joint name="iiwa14_joint_4" axis="0 0 1" limited="true" range="-2.09439510239 2.09439510239"/>
              <inertial euler="0 0 0" pos="0 0.067 0.034" mass="3.5" diaginertia="0.017 0.0164 0.006"/>
              <geom class="collision" type="mesh" mesh="iiwa14_link_4_mesh"/>
              <geom class="visual" type="mesh" mesh="iiwa14_link_4_mesh" material="iiwa14_orange"/>
              <body name="iiwa14_link_5" euler="-1.570796326794897 0 3.141592653589793" pos="0 0.1845 0">
                <joint name="iiwa14_joint_5" axis="0 0 1" limited="true" range="-2.96705972839 2.96705972839"/>
                <inertial euler="0 0 0" pos="0.0001 0.021 0.076" mass="3.5" diaginertia="0.01 0.0087 0.00449"/>
                <geom class="collision" type="mesh" mesh="iiwa14_link_5_mesh"/>
                <geom class="visual" type="mesh" mesh="iiwa14_link_5_mesh" material="iiwa14_grey"/>
                <body name="iiwa14_link_6" euler="1.570796326794897 0 0" pos="0 0 0.2155">
                  <joint name="iiwa14_joint_6" axis="0 0 1" limited="true" range="-2.09439510239 2.09439510239"/>
                  <inertial euler="0 0 0" pos="0 0.0006 0.0004" mass="1.8" diaginertia="0.0049 0.0047 0.0036"/>
                  <geom class="collision" type="mesh" mesh="iiwa14_link_6_mesh"/>
                  <geom class="visual" type="mesh" mesh="iiwa14_link_6_mesh" material="iiwa14_orange"/>
                  <body name="iiwa14_link_7" euler="-1.570796326794897 0 0" pos="0 0.081 0">
                    <joint name="iiwa14_joint_7" axis="0 0 1" limited="true" range="-3.05432619099 3.05432619099"/>
                    <inertial euler="0 0 0" pos="0 0 0.02" mass="1.2" diaginertia="0.001 0.001 0.001"/>
                    <geom class="collision" type="mesh" mesh="iiwa14_link_7_mesh"/>
                    <geom class="visual" type="mesh" mesh="iiwa14_link_7_mesh" material="iiwa14_grey"/>
                    <!-- <site name="ee_site" pos="0 0 0.05" euler="0 0 0" size="0.005, 0.005, 0.005"/> -->
                    <camera pos="0.1 0 0" euler="3.14159265359 0 -1.57079632679"/>
                    <body name="iiwa14_right_hand" pos="0 0 0.045" quat="1 0 0 0">
                                                    <!-- This camera points out from the eef. -->
                        <camera mode="fixed" name="iiwa14_eye_in_hand" pos="0.05 0 0" quat="0 0.707108 0.707108 0" fovy="75"/>
                        <!-- To add gripper -->
                        <include file="peg/peg_collision.xml"/>
                    </body>
                  </body>
                </body>
              </body>
            </body>
          </body>
        </body>
      </body>
    </body>
  </body>
</mujoco>
